2025-05-17 09:30:52.882 WARNING (SyncWorker_0) [homeassistant.loader] We found a custom integration backup_dropbox which has not been tested by Home Assistant. This component might cause stability problems, be sure to disable it if you experience issues with Home Assistant
2025-05-17 09:30:54.472 WARNING (MainThread) [aiohttp_fast_zlib] zlib_ng and isal are not available, falling back to zlib, performance will be degraded.
2025-05-17 09:31:01.089 WARNING (MainThread) [homeassistant.components.http.ban] Login attempt or request with invalid authentication from localhost (127.0.0.1). Requested URL: '/auth/token'. (Mozilla/5.0 (Macintosh; Intel Mac OS X 10_15_7) AppleWebKit/537.36 (KHTML, like Gecko) Chrome/136.0.0.0 Safari/537.36)
2025-05-17 09:31:01.206 WARNING (MainThread) [homeassistant.components.http.ban] Login attempt or request with invalid authentication from localhost (127.0.0.1). Requested URL: '/api/websocket'. (Mozilla/5.0 (Macintosh; Intel Mac OS X 10_15_7) AppleWebKit/537.36 (KHTML, like Gecko) Chrome/136.0.0.0 Safari/537.36)
2025-05-17 09:31:39.370 ERROR (MainThread) [homeassistant.config_entries] Error occurred loading flow for integration google_translate: No module named 'mutagen'
2025-05-17 09:31:39.371 ERROR (MainThread) [aiohttp.server] Error handling request
Traceback (most recent call last):
  File "/home/vscode/.local/lib/python3.12/site-packages/homeassistant/config_entries.py", line 3312, in _load_integration
    await integration.async_get_platform("config_flow")
  File "/home/vscode/.local/lib/python3.12/site-packages/homeassistant/loader.py", line 1108, in async_get_platform
    platforms = await self.async_get_platforms((platform_name,))
                ^^^^^^^^^^^^^^^^^^^^^^^^^^^^^^^^^^^^^^^^^^^^^^^^
  File "/home/vscode/.local/lib/python3.12/site-packages/homeassistant/loader.py", line 1185, in async_get_platforms
    import_future.result()
  File "/home/vscode/.local/lib/python3.12/site-packages/homeassistant/loader.py", line 1155, in async_get_platforms
    await self.hass.async_add_import_executor_job(
  File "/usr/local/lib/python3.12/concurrent/futures/thread.py", line 59, in run
    result = self.fn(*self.args, **self.kwargs)
             ^^^^^^^^^^^^^^^^^^^^^^^^^^^^^^^^^^
  File "/home/vscode/.local/lib/python3.12/site-packages/homeassistant/loader.py", line 1098, in _load_platforms
    platform_name: self._load_platform(platform_name)
                   ^^^^^^^^^^^^^^^^^^^^^^^^^^^^^^^^^^
  File "/home/vscode/.local/lib/python3.12/site-packages/homeassistant/loader.py", line 1272, in _load_platform
    cache[full_name] = self._import_platform(platform_name)
                       ^^^^^^^^^^^^^^^^^^^^^^^^^^^^^^^^^^^^
  File "/home/vscode/.local/lib/python3.12/site-packages/homeassistant/loader.py", line 1304, in _import_platform
    return importlib.import_module(f"{self.pkg_path}.{platform_name}")
           ^^^^^^^^^^^^^^^^^^^^^^^^^^^^^^^^^^^^^^^^^^^^^^^^^^^^^^^^^^^
  File "/home/vscode/.local/lib/python3.12/site-packages/homeassistant/util/loop.py", line 200, in protected_loop_func
    return func(*args, **kwargs)
           ^^^^^^^^^^^^^^^^^^^^^
  File "/usr/local/lib/python3.12/importlib/__init__.py", line 90, in import_module
    return _bootstrap._gcd_import(name[level:], package, level)
           ^^^^^^^^^^^^^^^^^^^^^^^^^^^^^^^^^^^^^^^^^^^^^^^^^^^^
  File "<frozen importlib._bootstrap>", line 1387, in _gcd_import
  File "<frozen importlib._bootstrap>", line 1360, in _find_and_load
  File "<frozen importlib._bootstrap>", line 1331, in _find_and_load_unlocked
  File "<frozen importlib._bootstrap>", line 935, in _load_unlocked
  File "<frozen importlib._bootstrap_external>", line 999, in exec_module
  File "<frozen importlib._bootstrap>", line 488, in _call_with_frames_removed
  File "/home/vscode/.local/lib/python3.12/site-packages/homeassistant/components/google_translate/config_flow.py", line 9, in <module>
    from homeassistant.components.tts import CONF_LANG
  File "/home/vscode/.local/lib/python3.12/site-packages/homeassistant/components/tts/__init__.py", line 22, in <module>
    import mutagen
ModuleNotFoundError: No module named 'mutagen'

The above exception was the direct cause of the following exception:

Traceback (most recent call last):
  File "/home/vscode/.local/lib/python3.12/site-packages/aiohttp/web_protocol.py", line 480, in _handle_request
    resp = await request_handler(request)
           ^^^^^^^^^^^^^^^^^^^^^^^^^^^^^^
  File "/home/vscode/.local/lib/python3.12/site-packages/aiohttp/web_app.py", line 569, in _handle
    return await handler(request)
           ^^^^^^^^^^^^^^^^^^^^^^
  File "/home/vscode/.local/lib/python3.12/site-packages/aiohttp/web_middlewares.py", line 117, in impl
    return await handler(request)
           ^^^^^^^^^^^^^^^^^^^^^^
  File "/home/vscode/.local/lib/python3.12/site-packages/homeassistant/components/http/security_filter.py", line 92, in security_filter_middleware
    return await handler(request)
           ^^^^^^^^^^^^^^^^^^^^^^
  File "/home/vscode/.local/lib/python3.12/site-packages/homeassistant/components/http/forwarded.py", line 83, in forwarded_middleware
    return await handler(request)
           ^^^^^^^^^^^^^^^^^^^^^^
  File "/home/vscode/.local/lib/python3.12/site-packages/homeassistant/components/http/request_context.py", line 26, in request_context_middleware
    return await handler(request)
           ^^^^^^^^^^^^^^^^^^^^^^
  File "/home/vscode/.local/lib/python3.12/site-packages/homeassistant/components/http/ban.py", line 86, in ban_middleware
    return await handler(request)
           ^^^^^^^^^^^^^^^^^^^^^^
  File "/home/vscode/.local/lib/python3.12/site-packages/homeassistant/components/http/auth.py", line 242, in auth_middleware
    return await handler(request)
           ^^^^^^^^^^^^^^^^^^^^^^
  File "/home/vscode/.local/lib/python3.12/site-packages/homeassistant/components/http/headers.py", line 32, in headers_middleware
    response = await handler(request)
               ^^^^^^^^^^^^^^^^^^^^^^
  File "/home/vscode/.local/lib/python3.12/site-packages/homeassistant/helpers/http.py", line 73, in handle
    result = await handler(request, **request.match_info)
             ^^^^^^^^^^^^^^^^^^^^^^^^^^^^^^^^^^^^^^^^^^^^
  File "/home/vscode/.local/lib/python3.12/site-packages/homeassistant/components/onboarding/views.py", line 241, in post
    await asyncio.gather(*(create_eager_task(coro) for coro in coros))
  File "/home/vscode/.local/lib/python3.12/site-packages/homeassistant/config_entries.py", line 1315, in async_init
    flow, result = await self._async_init(flow_id, handler, context, data)
                   ^^^^^^^^^^^^^^^^^^^^^^^^^^^^^^^^^^^^^^^^^^^^^^^^^^^^^^^
  File "/home/vscode/.local/lib/python3.12/site-packages/homeassistant/config_entries.py", line 1340, in _async_init
    flow = await self.async_create_flow(handler, context=context, data=data)
           ^^^^^^^^^^^^^^^^^^^^^^^^^^^^^^^^^^^^^^^^^^^^^^^^^^^^^^^^^^^^^^^^^
  File "/home/vscode/.local/lib/python3.12/site-packages/homeassistant/config_entries.py", line 1536, in async_create_flow
    handler = await _async_get_flow_handler(
              ^^^^^^^^^^^^^^^^^^^^^^^^^^^^^^
  File "/home/vscode/.local/lib/python3.12/site-packages/homeassistant/config_entries.py", line 3333, in _async_get_flow_handler
    await _load_integration(hass, domain, hass_config)
  File "/home/vscode/.local/lib/python3.12/site-packages/homeassistant/config_entries.py", line 3319, in _load_integration
    raise data_entry_flow.UnknownHandler from err
homeassistant.data_entry_flow.UnknownHandler
2025-05-17 09:31:44.411 ERROR (MainThread) [homeassistant.components.go2rtc] Could not find go2rtc docker binary
2025-05-17 09:31:44.412 ERROR (MainThread) [homeassistant.setup] Setup failed for 'go2rtc': Integration failed to initialize.
2025-05-17 09:31:44.684 ERROR (MainThread) [homeassistant.setup] Unable to set up dependencies of 'default_config'. Setup failed for dependencies: ['go2rtc']
2025-05-17 09:31:44.684 ERROR (MainThread) [homeassistant.setup] Setup failed for 'default_config': Could not setup dependencies: go2rtc
2025-05-17 09:31:44.685 WARNING (MainThread) [homeassistant.bootstrap] Support for the running Python version 3.12.10 is deprecated and will be removed in Home Assistant 2025.2; Please upgrade Python to 3.13
